pip._internal.exceptions.HashMismatch.body
b39b010629c8b51266320b1cc6db01bf