pip._internal.exceptions.HashError.body
c1ca0f60c3dadbfa246e9373abe2c7b0