pip._internal.exceptions.HashErrors.__init__
ace6df07056a30cde8ba1a56e2c26040