pip._internal.exceptions.HashError.__str__
596e0c731fde12b2f89dc59a175215da