pip._internal.exceptions.NoneMetadataError.__str__
0a9e905fc4fddd9005ed756eb3ae4541