
8anyio._backends._asyncio.DatagramProtocol.error_receivedg
[/home/kali/Documentos/API-de-X/env/lib/python3.12/site-packages/anyio/_backends/_asyncio.pyê	 ê	("2*ã
2
ë	 ë	(u
s

ë	 ë	(:+
)anyio._backends._asyncio.DatagramProtocol"
	exception"__id*#

__unknown_file (

exc*
3*3
3
_asyncio.py"
ì	 ì	(
implicit return:

ê	 ê	(+
excB-+
)anyio._backends._asyncio.DatagramProtocolH